<?xml version="1.0"?>
<robot xmlns:xacro="http://www.ros.org/wiki/xacro" name="my_robot">
  <!-- Definindo o link para o corpo do robô -->
  <link name="base_link">
    <visual>
      <geometry>
        <box size="0.5 0.3 0.1"/> <!-- Dimensões do corpo do robô -->
      </geometry>
      <material name="blue">
        <color rgba="1 1 1 1"/> <!-- Cor branca -->
      </material>
    </visual>
    <collision>
      <geometry>
        <box size="0.5 0.3 0.1"/> <!-- Dimensões do corpo do robô -->
      </geometry>
    </collision>
    <inertial>
      <mass value="1.0"/> <!-- Massa do corpo do robô -->
      <origin xyz="0 0 0.05" rpy="0 0 0"/> <!-- Elevação do corpo do robô -->
      <inertia ixx="0.1" ixy="0.0" ixz="0.0" iyy="0.1" iyz="0.0" izz="0.1"/> <!-- Tensor de inércia -->
    </inertial>
  </link>

  <!-- Definindo a roda esquerda -->
  <link name="left_wheel_link">
    <visual>
      <geometry>
        <cylinder radius="0.05" length="0.02"/> <!-- Dimensões da roda -->
      </geometry>
      <material name="black">
        <color rgba="0 0 0 1"/> <!-- Cor preta -->
      </material>
    </visual>
    <collision>
      <geometry>
        <cylinder radius="0.05" length="0.02"/> <!-- Dimensões da roda -->
      </geometry>
    </collision>
    <inertial>
      <mass value="0.2"/> <!-- Massa da roda -->
      <origin xyz="0 0 0" rpy="0 0 0"/>
      <inertia ixx="0.01" ixy="0.0" ixz="0.0" iyy="0.01" iyz="0.0" izz="0.01"/> <!-- Tensor de inércia -->
    </inertial>
  </link>

  <!-- Definindo a junta para conectar a roda esquerda ao corpo do robô -->
  <joint name="left_wheel_joint" type="continuous">
    <parent link="base_link"/>
    <child link="left_wheel_link"/>
    <origin xyz="0 0.16 0.0" rpy="1.5708 0 0"/> <!-- Posição da roda esquerda -->
    <axis xyz="0 1 0"/> <!-- Eixo de rotação da roda (vertical) -->
    <limit effort="10.0" lower="0" upper="3.14" velocity="1.0"/> <!-- Limites da junta -->
    <dynamics damping="0.1" friction="0.1"/> <!-- Dinâmica da junta -->
  </joint>

  <!-- Definindo a roda direita -->
  <link name="right_wheel_link">
    <visual>
      <geometry>
        <cylinder radius="0.05" length="0.02"/> <!-- Dimensões da roda -->
      </geometry>
      <material name="black">
        <color rgba="0 0 0 1"/> <!-- Cor preta -->
      </material>
    </visual>
    <collision>
      <geometry>
        <cylinder radius="0.05" length="0.02"/> <!-- Dimensões da roda -->
      </geometry>
    </collision>
    <inertial>
      <mass value="0.2"/> <!-- Massa da roda -->
      <origin xyz="0 0 0" rpy="0 0 0"/>
      <inertia ixx="0.01" ixy="0.0" ixz="0.0" iyy="0.01" iyz="0.0" izz="0.01"/> <!-- Tensor de inércia -->
    </inertial>
  </link>

  <!-- Definindo a junta para conectar a roda direita ao corpo do robô -->
  <joint name="right_wheel_joint" type="continuous">
    <parent link="base_link"/>
    <child link="right_wheel_link"/>
    <origin xyz="0 -0.16 0.0" rpy="1.5708 0 0"/> <!-- Posição da roda direita -->
    <axis xyz="0 1 0"/> <!-- Eixo de rotação da roda (vertical) -->
    <limit effort="10.0" lower="0" upper="3.14" velocity="1.0"/> <!-- Limites da junta -->
    <dynamics damping="0.1" friction="0.1"/> <!-- Dinâmica da junta -->
  </joint>

  <!-- Plugin do Gazebo para o controle da simulação -->
  <gazebo>
    <plugin name="gazebo_ros_control" filename="libgazebo_ros_control.so"/>
  </gazebo>

  <!-- Plugin do Gazebo para a roda esquerda -->
  <gazebo reference="left_wheel_link">
    <material>Gazebo/Black</material>
  </gazebo>

  <!-- Plugin do Gazebo para a roda direita -->
  <gazebo reference="right_wheel_link">
    <material>Gazebo/Black</material>
  </gazebo>
</robot>



